Workbook

Sheet Página2
B2: Scorização de Análise de Concorrência
B8: 1° | C8: Primeiro Passo - Defina o peso dos parâmetros a serem analisados
B13: Definição de Pesos | C13: Peso
B14: Posicionamento | C14: 1
B15: Público e Segmento Alvo | C15: 2
B16: Produtos e Serviços Oferecidos | C16: 3
B17: Precificação e Monetização | C17: 4
B18: Aquisição e Marketing | C18: 5
B19: Força da Marca e Reputação | C19: 3
B20: Tecnologias e Ferramentas | C20: 2
B21: Ecossistema e Composição | C21: 1
B23: Legenda para definir peso dos critérios
B24: 1 - Nenhuma interferência no negócio
B25: 2 - Pouca interferênca no negócio
B26: 3 - Pode interferir no negócio
B27: 4 - Interfere no negócio
B28: 5 - Muita interferência no negócio
B30: 2° | C30: Segundo passo: Defina o Market Share
B34: Definição de Market Share | C34: Faturamento Individual | D34: Faturamento Mercado | E34: Market Share
B35: Minha Empresa | C35: 13000000 | D35: =SUM($C$35:$C$40) -> 128000000 | E35: =C35/D35 -> 0.1015625
B36: Concorrente A | C36: 20000000 | D36: =SUM($C$35:$C$40) -> 128000000 | E36: =C36/D36 -> 0.15625
B37: Concorrente B | C37: 10000000 | D37: =SUM($C$35:$C$40) -> 128000000 | E37: =C37/D37 -> 0.078125
B38: Concorrente C | C38: 55000000 | D38: =SUM($C$35:$C$40) -> 128000000 | E38: =C38/D38 -> 0.4296875
B39: Concorrente D | C39: 7000000 | D39: =SUM($C$35:$C$40) -> 128000000 | E39: =C39/D39 -> 0.0546875
B40: Concorrente E | C40: 23000000 | D40: =SUM($C$35:$C$40) -> 128000000 | E40: =C40/D40 -> 0.1796875
C42: Insira o faturamento de cada empresa | D42: Soma dos faturamentos compôem o mercado | E42: Market Share do mercado acessado
B44: 3° | C44: Avalie o mercado nos critérios abaixo
B48: Avaliação | C48: Posicionamento | D48: Público e Segmento Alvo | E48: Produtos e Serviços Oferecidos | F48: Precificação e Monetização | G48: Aquisição e Marketing | H48: Força da Marca e Reputação | I48: Tecnologias e Ferramentas | J48: Ecossistema e Composição | K48: Pontuação final
B49: Minha Empresa | C49: 3 | D49: 1 | E49: 3 | F49: 3 | G49: 1 | H49: 1 | I49: 3 | J49: 3 | K49: =SUM((C49*$C$14),(D49*$C$15),(E49*$C$16),(F49*$C$17),(G49*$C$18),(H49*$C$19),(I49*$C$20),(J49*$C$21)) -> 43
B50: Concorrente A | C50: 1 | D50: 3 | E50: 1 | F50: 1 | G50: 1 | H50: 3 | I50: 5 | J50: 1 | K50: =SUM((C50*$C$14),(D50*$C$15),(E50*$C$16),(F50*$C$17),(G50*$C$18),(H50*$C$19),(I50*$C$20),(J50*$C$21)) -> 39
B51: Concorrente B | C51: 3 | D51: 1 | E51: 1 | F51: 3 | G51: 1 | H51: 1 | I51: 1 | J51: 1 | K51: =SUM((C51*$C$14),(D51*$C$15),(E51*$C$16),(F51*$C$17),(G51*$C$18),(H51*$C$19),(I51*$C$20),(J51*$C$21)) -> 31
B52: Concorrente C | C52: 5 | D52: 1 | E52: 1 | F52: 5 | G52: 3 | H52: 3 | I52: 5 | J52: 1 | K52: =SUM((C52*$C$14),(D52*$C$15),(E52*$C$16),(F52*$C$17),(G52*$C$18),(H52*$C$19),(I52*$C$20),(J52*$C$21)) -> 65
B53: Concorrente D | C53: 3 | D53: 5 | E53: 5 | F53: 3 | G53: 5 | H53: 1 | I53: 5 | J53: 1 | K53: =SUM((C53*$C$14),(D53*$C$15),(E53*$C$16),(F53*$C$17),(G53*$C$18),(H53*$C$19),(I53*$C$20),(J53*$C$21)) -> 79
B54: Concorrente E | C54: 1 | D54: 3 | E54: 1 | F54: 1 | G54: 3 | H54: 1 | I54: 5 | J54: 1 | K54: =SUM((C54*$C$14),(D54*$C$15),(E54*$C$16),(F54*$C$17),(G54*$C$18),(H54*$C$19),(I54*$C$20),(J54*$C$21)) -> 43
B56: Legenda para definir peso dos critérios
B57: 1 - Inferior ao meu negócio
B58: 3 - Equivalente ao meu negócio
B59: 5 - Superior ao meu negócio
B64: 4° | C64: Visualização Gráfica
B66: Organização de Dados | E66: Mapa de Concorrência
...
